<?xml version="1.0" ?>
<!-- =================================================================================== -->
<!-- |    This document was autogenerated by xacro from rosmaster_x3.urdf.xacro        | -->
<!-- |    EDITING THIS FILE BY HAND IS NOT RECOMMENDED                                 | -->
<!-- =================================================================================== -->
<robot name="rosmaster_x3">
  <link name="hi/base_footprint"/>
  <link name="hi/base_link">
    <visual>
      <geometry>
        <mesh filename="file:///home/suraj/ros2_ws/install/yahboom_rosmaster_description/share/yahboom_rosmaster_description/meshes/rosmaster_x3/visual/base_link_X3.STL"/>
      </geometry>
      <material name="green">
        <color rgba="0 0.7 0 1"/>
      </material>
      <origin rpy="0 0 0" xyz="0 0 0"/>
    </visual>
    <collision>
      <geometry>
        <box size="0.3 0.1386 0.19724999999999998"/>
      </geometry>
      <origin rpy="0 0 0" xyz="-0.031 0 0.10674999999999998"/>
    </collision>
    <inertial>
      <origin rpy="0 0 0" xyz="-0.031 0 0.10674999999999998"/>
      <mass value="4.6"/>
      <inertia ixx="0.022278383624999995" ixy="0.0" ixz="0.0" iyy="0.04941456562499999" iyz="0.0" izz="0.041863818"/>
    </inertial>
  </link>
  <gazebo reference="hi/base_link">
    <visual>
      <material>
        <ambient>0 0.7 0 1</ambient>
        <diffuse>0 0.7 0 1</diffuse>
        <specular>0 0.7 0 1</specular>
      </material>
    </visual>
  </gazebo>
  <joint name="hi/base_joint" type="fixed">
    <parent link="hi/base_footprint"/>
    <child link="hi/base_link"/>
    <origin rpy="0 0 0" xyz="0 0 0.0325"/>
  </joint>
  <link name="hi/front_left_wheel_link">
    <visual>
      <origin rpy="1.5707963267948966 0 0" xyz="0 0 0"/>
      <geometry>
        <mesh filename="file:///home/suraj/ros2_ws/install/yahboom_rosmaster_description/share/yahboom_rosmaster_description/meshes/rosmaster_x3/visual/front_left_wheel_X3.STL"/>
      </geometry>
      <material name="dark_gray">
        <color rgba="0.2 0.2 0.2 1.0"/>
      </material>
    </visual>
    <collision>
      <origin rpy="1.5707963267948966 0 0" xyz="0 0 0"/>
      <geometry>
        <cylinder length="0.0304" radius="0.0325"/>
      </geometry>
    </collision>
    <inertial>
      <origin rpy="0 0 0" xyz="0 0 0"/>
      <mass value="9.1"/>
      <inertia ixx="0.0031037900833333332" ixy="0" ixz="0" iyy="0.0048059375" iyz="0" izz="0.0031037900833333332"/>
    </inertial>
  </link>
  <joint name="hi/front_left_wheel_joint" type="continuous">
    <axis xyz="0 1 0"/>
    <parent link="hi/base_link"/>
    <child link="hi/front_left_wheel_link"/>
    <origin rpy="0 0 0" xyz="0.08 0.07450000000000001 -0.0325"/>
  </joint>
  <gazebo reference="hi/front_left_wheel_link">
    <surface>
      <friction>
        <ode>
          <mu>1.0</mu>
          <mu2>0.0</mu2>
        </ode>
      </friction>
    </surface>
    <visual>
      <material>
        <ambient>0.2 0.2 0.2 1.0</ambient>
        <diffuse>0.2 0.2 0.2 1.0</diffuse>
        <specular>0.2 0.2 0.2 1.0</specular>
        <emissive>0.0 0.0 0.0 0.0</emissive>
      </material>
    </visual>
  </gazebo>
  <link name="hi/front_right_wheel_link">
    <visual>
      <origin rpy="1.5707963267948966 0 0" xyz="0 0 0"/>
      <geometry>
        <mesh filename="file:///home/suraj/ros2_ws/install/yahboom_rosmaster_description/share/yahboom_rosmaster_description/meshes/rosmaster_x3/visual/front_right_wheel_X3.STL"/>
      </geometry>
      <material name="dark_gray">
        <color rgba="0.2 0.2 0.2 1.0"/>
      </material>
    </visual>
    <collision>
      <origin rpy="1.5707963267948966 0 0" xyz="0 0 0"/>
      <geometry>
        <cylinder length="0.0304" radius="0.0325"/>
      </geometry>
    </collision>
    <inertial>
      <origin rpy="0 0 0" xyz="0 0 0"/>
      <mass value="9.1"/>
      <inertia ixx="0.0031037900833333332" ixy="0" ixz="0" iyy="0.0048059375" iyz="0" izz="0.0031037900833333332"/>
    </inertial>
  </link>
  <joint name="hi/front_right_wheel_joint" type="continuous">
    <axis xyz="0 1 0"/>
    <parent link="hi/base_link"/>
    <child link="hi/front_right_wheel_link"/>
    <origin rpy="0 0 0" xyz="0.08 -0.07450000000000001 -0.0325"/>
  </joint>
  <gazebo reference="hi/front_right_wheel_link">
    <surface>
      <friction>
        <ode>
          <mu>1.0</mu>
          <mu2>0.0</mu2>
        </ode>
      </friction>
    </surface>
    <visual>
      <material>
        <ambient>0.2 0.2 0.2 1.0</ambient>
        <diffuse>0.2 0.2 0.2 1.0</diffuse>
        <specular>0.2 0.2 0.2 1.0</specular>
        <emissive>0.0 0.0 0.0 0.0</emissive>
      </material>
    </visual>
  </gazebo>
  <link name="hi/back_left_wheel_link">
    <visual>
      <origin rpy="1.5707963267948966 0 0" xyz="0 0 0"/>
      <geometry>
        <mesh filename="file:///home/suraj/ros2_ws/install/yahboom_rosmaster_description/share/yahboom_rosmaster_description/meshes/rosmaster_x3/visual/back_left_wheel_X3.STL"/>
      </geometry>
      <material name="dark_gray">
        <color rgba="0.2 0.2 0.2 1.0"/>
      </material>
    </visual>
    <collision>
      <origin rpy="1.5707963267948966 0 0" xyz="0 0 0"/>
      <geometry>
        <cylinder length="0.0304" radius="0.0325"/>
      </geometry>
    </collision>
    <inertial>
      <origin rpy="0 0 0" xyz="0 0 0"/>
      <mass value="9.1"/>
      <inertia ixx="0.0031037900833333332" ixy="0" ixz="0" iyy="0.0048059375" iyz="0" izz="0.0031037900833333332"/>
    </inertial>
  </link>
  <joint name="hi/back_left_wheel_joint" type="continuous">
    <axis xyz="0 1 0"/>
    <parent link="hi/base_link"/>
    <child link="hi/back_left_wheel_link"/>
    <origin rpy="0 0 0" xyz="-0.08 0.07450000000000001 -0.0325"/>
  </joint>
  <gazebo reference="hi/back_left_wheel_link">
    <surface>
      <friction>
        <ode>
          <mu>1.0</mu>
          <mu2>0.0</mu2>
        </ode>
      </friction>
    </surface>
    <visual>
      <material>
        <ambient>0.2 0.2 0.2 1.0</ambient>
        <diffuse>0.2 0.2 0.2 1.0</diffuse>
        <specular>0.2 0.2 0.2 1.0</specular>
        <emissive>0.0 0.0 0.0 0.0</emissive>
      </material>
    </visual>
  </gazebo>
  <link name="hi/back_right_wheel_link">
    <visual>
      <origin rpy="1.5707963267948966 0 0" xyz="0 0 0"/>
      <geometry>
        <mesh filename="file:///home/suraj/ros2_ws/install/yahboom_rosmaster_description/share/yahboom_rosmaster_description/meshes/rosmaster_x3/visual/back_right_wheel_X3.STL"/>
      </geometry>
      <material name="dark_gray">
        <color rgba="0.2 0.2 0.2 1.0"/>
      </material>
    </visual>
    <collision>
      <origin rpy="1.5707963267948966 0 0" xyz="0 0 0"/>
      <geometry>
        <cylinder length="0.0304" radius="0.0325"/>
      </geometry>
    </collision>
    <inertial>
      <origin rpy="0 0 0" xyz="0 0 0"/>
      <mass value="9.1"/>
      <inertia ixx="0.0031037900833333332" ixy="0" ixz="0" iyy="0.0048059375" iyz="0" izz="0.0031037900833333332"/>
    </inertial>
  </link>
  <joint name="hi/back_right_wheel_joint" type="continuous">
    <axis xyz="0 1 0"/>
    <parent link="hi/base_link"/>
    <child link="hi/back_right_wheel_link"/>
    <origin rpy="0 0 0" xyz="-0.08 -0.07450000000000001 -0.0325"/>
  </joint>
  <gazebo reference="hi/back_right_wheel_link">
    <surface>
      <friction>
        <ode>
          <mu>1.0</mu>
          <mu2>0.0</mu2>
        </ode>
      </friction>
    </surface>
    <visual>
      <material>
        <ambient>0.2 0.2 0.2 1.0</ambient>
        <diffuse>0.2 0.2 0.2 1.0</diffuse>
        <specular>0.2 0.2 0.2 1.0</specular>
        <emissive>0.0 0.0 0.0 0.0</emissive>
      </material>
    </visual>
  </gazebo>
  <link name="hi/cam_1_link">
    <visual>
      <origin rpy="1.5707963267948966 0.0 1.5707963267948966" xyz="0 0 0"/>
      <geometry>
        <mesh filename="file:///home/suraj/ros2_ws/install/yahboom_rosmaster_description/share/yahboom_rosmaster_description/meshes/intel_realsense/visual/d435.stl"/>
      </geometry>
      <material name="aluminum">
        <color rgba="0.5 0.5 0.5 1"/>
      </material>
    </visual>
    <inertial>
      <mass value="0.072"/>
      <origin rpy="0 0 0" xyz="0 0 0"/>
      <inertia ixx="0.003881243" ixy="0.0" ixz="0.0" iyy="0.00049894" iyz="0.0" izz="0.003879257"/>
    </inertial>
  </link>
  <joint name="hi/cam_1_joint" type="fixed">
    <parent link="hi/base_link"/>
    <child link="hi/cam_1_link"/>
    <origin rpy="0 -0.50 0" xyz="0.105 0 0.05"/>
  </joint>
  <joint name="hi/cam_1_depth_joint" type="fixed">
    <origin rpy="0 0 0" xyz="0 0 0"/>
    <parent link="hi/cam_1_link"/>
    <child link="hi/cam_1_depth_frame"/>
  </joint>
  <link name="hi/cam_1_depth_frame"/>
  <joint name="hi/cam_1_depth_optical_joint" type="fixed">
    <origin rpy="-1.5707963267948966 0 -1.5707963267948966" xyz="0 0 0"/>
    <parent link="hi/cam_1_depth_frame"/>
    <child link="hi/cam_1_depth_optical_frame"/>
  </joint>
  <link name="hi/cam_1_depth_optical_frame"/>
  <joint name="hi/cam_1_infra1_joint" type="fixed">
    <origin rpy="0 0 0" xyz="0 0 0"/>
    <parent link="hi/cam_1_link"/>
    <child link="hi/cam_1_infra1_frame"/>
  </joint>
  <link name="hi/cam_1_infra1_frame"/>
  <joint name="hi/cam_1_infra1_optical_joint" type="fixed">
    <origin rpy="-1.5707963267948966 0 -1.5707963267948966" xyz="0 0 0"/>
    <parent link="hi/cam_1_infra1_frame"/>
    <child link="hi/cam_1_infra1_optical_frame"/>
  </joint>
  <link name="hi/cam_1_infra1_optical_frame"/>
  <joint name="hi/cam_1_infra2_joint" type="fixed">
    <origin rpy="0 0 0" xyz="0 -0.05 0"/>
    <parent link="hi/cam_1_link"/>
    <child link="hi/cam_1_infra2_frame"/>
  </joint>
  <link name="hi/cam_1_infra2_frame"/>
  <joint name="hi/cam_1_infra2_optical_joint" type="fixed">
    <origin rpy="-1.5707963267948966 0 -1.5707963267948966" xyz="0 0 0"/>
    <parent link="hi/cam_1_infra2_frame"/>
    <child link="hi/cam_1_infra2_optical_frame"/>
  </joint>
  <link name="hi/cam_1_infra2_optical_frame"/>
  <joint name="hi/cam_1_color_joint" type="fixed">
    <origin rpy="0 0 0" xyz="0 0.015 0"/>
    <parent link="hi/cam_1_link"/>
    <child link="hi/cam_1_color_frame"/>
  </joint>
  <link name="hi/cam_1_color_frame"/>
  <joint name="hi/cam_1_color_optical_joint" type="fixed">
    <origin rpy="-1.5707963267948966 0 -1.5707963267948966" xyz="0 0 0"/>
    <parent link="hi/cam_1_color_frame"/>
    <child link="hi/cam_1_color_optical_frame"/>
  </joint>
  <link name="hi/cam_1_color_optical_frame"/>
  <gazebo reference="hi/cam_1_link">
    <sensor name="hi/cam_1" type="rgbd_camera">
      <camera>
        <horizontal_fov>1.5184</horizontal_fov>
        <image>
          <width>424</width>
          <height>240</height>
        </image>
        <clip>
          <near>0.05</near>
          <far>1.5</far>
        </clip>
      </camera>
      <always_on>1</always_on>
      <gz_frame_id>hi/cam_1_depth_optical_frame</gz_frame_id>
      <topic>cam_1</topic>
      <update_rate>2</update_rate>
      <visualize>True</visualize>
    </sensor>
  </gazebo>
  <link name="hi/laser_frame">
    <visual>
      <origin rpy="-1.5707963267948966 0 0" xyz="0 0 0"/>
      <geometry>
        <mesh filename="file:///home/suraj/ros2_ws/install/yahboom_rosmaster_description/share/yahboom_rosmaster_description/meshes/rplidar/rplidar_s2.stl" scale="0.001 0.001 0.001"/>
      </geometry>
      <material name="rplidar_black">
        <color rgba="0.1 0.1 0.1 1"/>
      </material>
    </visual>
    <inertial>
      <mass value="0.185"/>
      <origin rpy="0 0 0" xyz="0 0 0"/>
      <inertia ixx="9.297467916666665e-05" ixy="0.0" ixz="0.0" iyy="9.297467916666665e-05" iyz="0.0" izz="0.000137108125"/>
    </inertial>
  </link>
  <joint name="hi/laser_frame_joint" type="fixed">
    <parent link="hi/base_link"/>
    <child link="hi/laser_frame"/>
    <origin rpy="0 0 0" xyz="0 0 0.0825"/>
  </joint>
  <gazebo reference="hi/laser_frame">
    <material>
      <ambient>0.1 0.1 0.1 1</ambient>
      <diffuse>0.1 0.1 0.1 1</diffuse>
      <specular>0.1 0.1 0.1 1</specular>
    </material>
    <sensor name="hi/lidar_sensor" type="gpu_lidar">
      <topic>scan</topic>
      <update_rate>10</update_rate>
      <always_on>True</always_on>
      <visualize>False</visualize>
      <ray>
        <scan>
          <horizontal>
            <samples>720</samples>
            <resolution>1</resolution>
            <min_angle>-3.14159</min_angle>
            <max_angle>3.14159</max_angle>
          </horizontal>
          <vertical>
            <samples>1</samples>
            <resolution>1</resolution>
            <min_angle>0</min_angle>
            <max_angle>0</max_angle>
          </vertical>
        </scan>
        <range>
          <min>0.20</min>
          <max>30.0</max>
          <resolution>0.013</resolution>
        </range>
      </ray>
      <gz_frame_id>hi/laser_frame</gz_frame_id>
    </sensor>
  </gazebo>
  <link name="hi/imu_link">
    <visual>
      <origin rpy="0 0 0" xyz="0 0 0"/>
      <geometry>
        <box size="0.03899 0.03785 0.01338"/>
      </geometry>
      <material name="imu_black">
        <color rgba="0.1 0.1 0.1 1"/>
      </material>
    </visual>
    <inertial>
      <mass value="0.031"/>
      <origin rpy="0 0 0" xyz="0 0 0"/>
      <inertia ixx="4.163421158333333e-06" ixy="0.0" ixz="0.0" iyy="4.389714958333333e-06" iyz="0.0" izz="7.6281767166666665e-06"/>
    </inertial>
  </link>
  <joint name="hi/imu_joint" type="fixed">
    <parent link="hi/base_link"/>
    <child link="hi/imu_link"/>
    <origin rpy="0 0 0" xyz="0 0 0.006"/>
  </joint>
  <gazebo reference="hi/imu_link">
    <material>
      <ambient>0.1 0.1 0.1 1</ambient>
      <diffuse>0.1 0.1 0.1 1</diffuse>
      <specular>0.1 0.1 0.1 1</specular>
    </material>
    <sensor name="hi/imu_sensor" type="imu">
      <topic>imu/data</topic>
      <update_rate>15.0</update_rate>
      <always_on>True</always_on>
      <visualize>False</visualize>
      <gz_frame_id>hi/imu_link</gz_frame_id>
    </sensor>
  </gazebo>
  <ros2_control name="RobotSystem" type="system">
    <hardware>
    </hardware>
    <joint name="hi/front_left_wheel_joint">
      <command_interface name="velocity">
        <param name="min">-50.0</param>
        <param name="max">50.0</param>
      </command_interface>
      <state_interface name="position"/>
      <state_interface name="velocity"/>
    </joint>
    <joint name="hi/front_right_wheel_joint">
      <command_interface name="velocity">
        <param name="min">-50.0</param>
        <param name="max">50.0</param>
      </command_interface>
      <state_interface name="position"/>
      <state_interface name="velocity"/>
    </joint>
    <joint name="hi/back_left_wheel_joint">
      <command_interface name="velocity">
        <param name="min">-50.0</param>
        <param name="max">50.0</param>
      </command_interface>
      <state_interface name="position"/>
      <state_interface name="velocity"/>
    </joint>
    <joint name="hi/back_right_wheel_joint">
      <command_interface name="velocity">
        <param name="min">-50.0</param>
        <param name="max">50.0</param>
      </command_interface>
      <state_interface name="position"/>
      <state_interface name="velocity"/>
    </joint>
  </ros2_control>
</robot>
