<?xml version="1.0" ?>
<!-- =================================================================================== -->
<!-- |    This document was autogenerated by xacro from ./x3_uav.urdf.xacro            | -->
<!-- |    EDITING THIS FILE BY HAND IS NOT RECOMMENDED                                 | -->
<!-- =================================================================================== -->
<robot name="x3_uav_description">
  <!-- ====================== MATERIALS ====================== -->
  <material name="blue">
    <color rgba="0 0 1 1"/>
  </material>
  <material name="red">
    <color rgba="1 0 0 1"/>
  </material>
  <!-- ====================== DUMMY BASE FOOTPRINT LINK (THIS FIXES TF TREE) ====================== -->
  <link name="base_footprint"/>
  <!-- ====================== BASE LINK ====================== -->
  <link name="base_link">
    <inertial>
      <origin rpy="0 0 0" xyz="0 0 0"/>
      <mass value="1.5"/>
      <inertia ixx="0.0347563" ixy="0" ixz="0" iyy="0.07" iyz="0" izz="0.0977"/>
    </inertial>
    <collision name="base_link_inertia_collision">
      <origin rpy="0 0 0" xyz="0 0 0"/>
      <geometry>
        <box size="0.47 0.47 0.11"/>
      </geometry>
    </collision>
    <visual name="base_link_inertia_visual">
      <origin rpy="0 0 0" xyz="0 0 0"/>
      <geometry>
        <mesh filename="package://x3_uav_description/meshes/x3.dae" scale="1 1 1"/>
      </geometry>
    </visual>
  </link>
  <!-- ====================== ROTOR 0 ====================== -->
  <link name="rotor_0">
    <inertial>
      <origin rpy="0 0 0" xyz="0 0 0"/>
      <mass value="0.005"/>
      <inertia ixx="9.75e-07" ixy="0" ixz="0" iyy="4.17041e-05" iyz="0" izz="4.26041e-05"/>
    </inertial>
    <collision name="rotor_0_collision">
      <origin rpy="0 0 0" xyz="0 0 0"/>
      <geometry>
        <cylinder length="0.005" radius="0.1"/>
      </geometry>
    </collision>
    <visual name="rotor_0_visual">
      <origin rpy="0 0 0" xyz="0 0 0"/>
      <geometry>
        <mesh filename="package://x3_uav_description/meshes/propeller_ccw.dae" scale="0.1 0.1 0.1"/>
      </geometry>
      <material name="blue"/>
    </visual>
  </link>
  <!-- ====================== ROTOR 1 ====================== -->
  <link name="rotor_1">
    <inertial>
      <origin rpy="0 0 0" xyz="0 0 0"/>
      <mass value="0.005"/>
      <inertia ixx="9.75e-07" ixy="0" ixz="0" iyy="4.17041e-05" iyz="0" izz="4.26041e-05"/>
    </inertial>
    <collision name="rotor_1_collision">
      <origin rpy="0 0 0" xyz="0 0 0"/>
      <geometry>
        <cylinder length="0.005" radius="0.1"/>
      </geometry>
    </collision>
    <visual name="rotor_1_visual">
      <origin rpy="0 0 0" xyz="0 0 0"/>
      <geometry>
        <mesh filename="package://x3_uav_description/meshes/propeller_ccw.dae" scale="0.1 0.1 0.1"/>
      </geometry>
      <material name="red"/>
    </visual>
  </link>
  <!-- ====================== ROTOR 2 ====================== -->
  <link name="rotor_2">
    <inertial>
      <origin rpy="0 0 0" xyz="0 0 0"/>
      <mass value="0.005"/>
      <inertia ixx="9.75e-07" ixy="0" ixz="0" iyy="4.17041e-05" iyz="0" izz="4.26041e-05"/>
    </inertial>
    <collision name="rotor_2_collision">
      <origin rpy="0 0 0" xyz="0 0 0"/>
      <geometry>
        <cylinder length="0.005" radius="0.1"/>
      </geometry>
    </collision>
    <visual name="rotor_2_visual">
      <origin rpy="0 0 0" xyz="0 0 0"/>
      <geometry>
        <mesh filename="package://x3_uav_description/meshes/propeller_cw.dae" scale="0.1 0.1 0.1"/>
      </geometry>
      <material name="blue"/>
    </visual>
  </link>
  <!-- ====================== ROTOR 3 ====================== -->
  <link name="rotor_3">
    <inertial>
      <origin rpy="0 0 0" xyz="0 0 0"/>
      <mass value="0.005"/>
      <inertia ixx="9.75e-07" ixy="0" ixz="0" iyy="4.17041e-05" iyz="0" izz="4.26041e-05"/>
    </inertial>
    <collision name="rotor_3_collision">
      <origin rpy="0 0 0" xyz="0 0 0"/>
      <geometry>
        <cylinder length="0.005" radius="0.1"/>
      </geometry>
    </collision>
    <visual name="rotor_3_visual">
      <origin rpy="0 0 0" xyz="0 0 0"/>
      <geometry>
        <mesh filename="package://x3_uav_description/meshes/propeller_cw.dae" scale="0.1 0.1 0.1"/>
      </geometry>
      <material name="red"/>
    </visual>
  </link>
  <!-- ====================== IMU LINK ====================== -->
  <link name="imu_link">
    <visual>
      <origin rpy="0 0 0" xyz="0 0 0.01"/>
      <geometry>
        <box size="0.03 0.03 0.01"/>
      </geometry>
      <!-- <material name="black"/> -->
    </visual>
    <inertial>
      <mass value="0.01"/>
      <origin xyz="0 0 0"/>
      <inertia ixx="1e-6" ixy="0" ixz="0" iyy="1e-6" iyz="0" izz="1e-6"/>
    </inertial>
  </link>
  <!-- ====================== BASE FOOTPRINT TO BASE JOINT ====================== -->
  <joint name="base_footprint_to_base" type="fixed">
    <parent link="base_footprint"/>
    <child link="base_link"/>
    <origin rpy="0 0 0" xyz="0 0 0.053302"/>
  </joint>
  <!-- ====================== ROTOR 0 JOINT ====================== -->
  <!-- <joint name="${frame_prefix}rotor_0_joint" type="continuous"> -->
  <joint name="rotor_0_joint" type="revolute">
    <parent link="base_link"/>
    <child link="rotor_0"/>
    <origin rpy="0 0 0" xyz="0.13 -0.22 0.023"/>
    <axis xyz="0 0 1"/>
    <limit effort="10" lower="-1e16" upper="1e16" velocity="100"/>
    <!-- for continuos joint remove this line-->
    <dynamics damping="0.0" friction="0.0"/>
  </joint>
  <!-- ====================== ROTOR 1 JOINT ====================== -->
  <!-- <joint name="${frame_prefix}rotor_1_joint" type="continuous"> -->
  <joint name="rotor_1_joint" type="revolute">
    <parent link="base_link"/>
    <child link="rotor_1"/>
    <origin rpy="0 0 0" xyz="-0.13 0.2 0.023"/>
    <axis xyz="0 0 1"/>
    <limit effort="10" lower="-1e16" upper="1e16" velocity="100"/>
    <!-- for continuos joint remove this line-->
    <dynamics damping="0.0" friction="0.0"/>
  </joint>
  <!-- ====================== ROTOR 2 JOINT ====================== -->
  <!-- <joint name="${frame_prefix}rotor_2_joint" type="continuous"> -->
  <joint name="rotor_2_joint" type="revolute">
    <parent link="base_link"/>
    <child link="rotor_2"/>
    <origin rpy="0 0 0" xyz="0.13 0.22 0.023"/>
    <axis xyz="0 0 1"/>
    <limit effort="10" lower="-1e16" upper="1e16" velocity="100"/>
    <!-- for continuos joint remove this line-->
    <dynamics damping="0.0" friction="0.0"/>
  </joint>
  <!-- ====================== ROTOR 3 JOINT ====================== -->
  <!-- <joint name="${frame_prefix}rotor_3_joint" type="continuous"> -->
  <joint name="rotor_3_joint" type="revolute">
    <parent link="base_link"/>
    <child link="rotor_3"/>
    <origin rpy="0 0 0" xyz="-0.13 -0.2 0.023"/>
    <axis xyz="0 0 1"/>
    <limit effort="10" lower="-1e16" upper="1e16" velocity="100"/>
    <!-- for continuos joint remove this line-->
    <dynamics damping="0.0" friction="0.0"/>
  </joint>
  <!-- ====================== IMU JOINT ====================== -->
  <joint name="imu_joint" type="fixed">
    <parent link="base_link"/>
    <child link="imu_link"/>
    <origin rpy="0 0 0" xyz="0.0 0.0 0.01"/>
  </joint>
  <gazebo reference="imu_link">
    <sensor name="imu" type="imu">
      <always_on>true</always_on>
      <update_rate>100</update_rate>
      <visualize>true</visualize>
      <topic>/imu/data</topic>
    </sensor>
  </gazebo>
  <!-- ====================== MOTOR 0 (CCW) ====================== -->
  <gazebo>
    <plugin filename="ignition-gazebo-multicopter-motor-model-system" name="gz::sim::systems::MulticopterMotorModel">
      <robotNamespace></robotNamespace>
      <jointName>rotor_0_joint</jointName>
      <linkName>rotor_0</linkName>
      <turningDirection>ccw</turningDirection>
      <timeConstantUp>0.0125</timeConstantUp>
      <timeConstantDown>0.025</timeConstantDown>
      <maxRotVelocity>800.0</maxRotVelocity>
      <motorConstant>8.54858e-06</motorConstant>
      <momentConstant>0.016</momentConstant>
      <commandSubTopic>gazebo/command/motor_speed</commandSubTopic>
      <motorNumber>0</motorNumber>
      <rotorDragCoefficient>8.06428e-05</rotorDragCoefficient>
      <rollingMomentCoefficient>1e-06</rollingMomentCoefficient>
      <motorSpeedPubTopic>motor_speed/0</motorSpeedPubTopic>
      <rotorVelocitySlowdownSim>10</rotorVelocitySlowdownSim>
      <motorType>velocity</motorType>
    </plugin>
  </gazebo>
  <!-- ====================== MOTOR 1 (CCW) ====================== -->
  <gazebo>
    <plugin filename="ignition-gazebo-multicopter-motor-model-system" name="gz::sim::systems::MulticopterMotorModel">
      <robotNamespace></robotNamespace>
      <jointName>rotor_1_joint</jointName>
      <linkName>rotor_1</linkName>
      <turningDirection>ccw</turningDirection>
      <timeConstantUp>0.0125</timeConstantUp>
      <timeConstantDown>0.025</timeConstantDown>
      <maxRotVelocity>800.0</maxRotVelocity>
      <motorConstant>8.54858e-06</motorConstant>
      <momentConstant>0.016</momentConstant>
      <commandSubTopic>gazebo/command/motor_speed</commandSubTopic>
      <motorNumber>1</motorNumber>
      <rotorDragCoefficient>8.06428e-05</rotorDragCoefficient>
      <rollingMomentCoefficient>1e-06</rollingMomentCoefficient>
      <motorSpeedPubTopic>motor_speed/1</motorSpeedPubTopic>
      <rotorVelocitySlowdownSim>10</rotorVelocitySlowdownSim>
      <motorType>velocity</motorType>
    </plugin>
  </gazebo>
  <!-- ====================== MOTOR 2 (CW) ====================== -->
  <gazebo>
    <plugin filename="ignition-gazebo-multicopter-motor-model-system" name="gz::sim::systems::MulticopterMotorModel">
      <robotNamespace></robotNamespace>
      <jointName>rotor_2_joint</jointName>
      <linkName>rotor_2</linkName>
      <turningDirection>cw</turningDirection>
      <timeConstantUp>0.0125</timeConstantUp>
      <timeConstantDown>0.025</timeConstantDown>
      <maxRotVelocity>800.0</maxRotVelocity>
      <motorConstant>8.54858e-06</motorConstant>
      <momentConstant>0.016</momentConstant>
      <commandSubTopic>gazebo/command/motor_speed</commandSubTopic>
      <motorNumber>2</motorNumber>
      <rotorDragCoefficient>8.06428e-05</rotorDragCoefficient>
      <rollingMomentCoefficient>1e-06</rollingMomentCoefficient>
      <motorSpeedPubTopic>motor_speed/2</motorSpeedPubTopic>
      <rotorVelocitySlowdownSim>10</rotorVelocitySlowdownSim>
      <motorType>velocity</motorType>
    </plugin>
  </gazebo>
  <!-- ====================== MOTOR 3 (CW) ====================== -->
  <gazebo>
    <plugin filename="ignition-gazebo-multicopter-motor-model-system" name="gz::sim::systems::MulticopterMotorModel">
      <robotNamespace></robotNamespace>
      <jointName>rotor_3_joint</jointName>
      <linkName>rotor_3</linkName>
      <turningDirection>cw</turningDirection>
      <timeConstantUp>0.0125</timeConstantUp>
      <timeConstantDown>0.025</timeConstantDown>
      <maxRotVelocity>800.0</maxRotVelocity>
      <motorConstant>8.54858e-06</motorConstant>
      <momentConstant>0.016</momentConstant>
      <commandSubTopic>gazebo/command/motor_speed</commandSubTopic>
      <motorNumber>3</motorNumber>
      <rotorDragCoefficient>8.06428e-05</rotorDragCoefficient>
      <rollingMomentCoefficient>1e-06</rollingMomentCoefficient>
      <motorSpeedPubTopic>motor_speed/3</motorSpeedPubTopic>
      <rotorVelocitySlowdownSim>10</rotorVelocitySlowdownSim>
      <motorType>velocity</motorType>
    </plugin>
  </gazebo>
  <!-- ====================== VELOCITY CONTROL PLUGIN ====================== -->
  <gazebo>
    <plugin filename="ignition-gazebo-multicopter-control-system" name="gz::sim::systems::MulticopterVelocityControl">
      <robotNamespace></robotNamespace>
      <commandSubTopic>cmd_vel</commandSubTopic>
      <enableSubTopic>enable</enableSubTopic>
      <comLinkName>base_link</comLinkName>
      <velocityGain>2.7 2.7 2.7</velocityGain>
      <attitudeGain>2 3 0.15</attitudeGain>
      <angularRateGain>0.4 0.52 0.18</angularRateGain>
      <maximumLinearAcceleration>1 1 2</maximumLinearAcceleration>
      <maximumLinearVelocity>5 5 5</maximumLinearVelocity>
      <maximumAngularVelocity>3 3 3</maximumAngularVelocity>
      <linearVelocityNoiseMean>0 0 0</linearVelocityNoiseMean>
      <linearVelocityNoiseStdDev>0.1105 0.1261 0.0947</linearVelocityNoiseStdDev>
      <angularVelocityNoiseMean>0 0 0</angularVelocityNoiseMean>
      <angularVelocityNoiseStdDev>0.004 0.004 0.004</angularVelocityNoiseStdDev>
      <rotorConfiguration>
        <rotor>
          <jointName>rotor_0_joint</jointName>
          <forceConstant>8.54858e-06</forceConstant>
          <momentConstant>0.016</momentConstant>
          <direction>1</direction>
        </rotor>
        <rotor>
          <jointName>rotor_1_joint</jointName>
          <forceConstant>8.54858e-06</forceConstant>
          <momentConstant>0.016</momentConstant>
          <direction>1</direction>
        </rotor>
        <rotor>
          <jointName>rotor_2_joint</jointName>
          <forceConstant>8.54858e-06</forceConstant>
          <momentConstant>0.016</momentConstant>
          <direction>-1</direction>
        </rotor>
        <rotor>
          <jointName>rotor_3_joint</jointName>
          <forceConstant>8.54858e-06</forceConstant>
          <momentConstant>0.016</momentConstant>
          <direction>-1</direction>
        </rotor>
      </rotorConfiguration>
    </plugin>
  </gazebo>
  <!-- ====================== ODOMETRY PUBLISHER ====================== -->
  <gazebo>
    <plugin filename="ignition-gazebo-odometry-publisher-system" name="ignition::gazebo::systems::OdometryPublisher">
      <odom_frame>odom</odom_frame>
      <robot_base_frame>base_footprint</robot_base_frame>
      <odom_publish_frequency>50</odom_publish_frequency>
      <odom_topic>odom</odom_topic>
      <odom_covariance_topic>odometry_with_covariance</odom_covariance_topic>
      <namespace></namespace>
      <tf_topic>/tf</tf_topic>
      <dimensions>2</dimensions>
    </plugin>
  </gazebo>
  <!-- ====================== JOINT STATE PUBLISHER ====================== -->
  <gazebo>
    <plugin filename="ignition-gazebo-joint-state-publisher-system" name="ignition::gazebo::systems::JointStatePublisher">
      <namespace></namespace>
      <topic>joint_states</topic>
      <joint_name_prefix></joint_name_prefix>
      <update_rate>50</update_rate>
    </plugin>
  </gazebo>
</robot>
